<?xml version="1.0" encoding="utf-8"?>
<!-- This URDF was automatically created by SolidWorks to URDF Exporter! Originally created by Stephen Brawner (brawner@gmail.com) 
     Commit Version: 1.6.0-4-g7f85cfe  Build Version: 1.6.7995.38578
     For more information, please see http://wiki.ros.org/sw_urdf_exporter -->
<robot
  name="drone">
  <link
    name="base_link">
    <inertial>
      <origin
        xyz="0.015986 -0.02573 0.24751"
        rpy="0 0 0" />
      <mass
        value="1.128" />
      <inertia
        ixx="0.0030744"
        ixy="1.1642E-06"
        ixz="-7.2631E-05"
        iyy="0.0050956"
        iyz="2.9256E-07"
        izz="0.0076564" />
    </inertial>
    <visual>
      <origin
        xyz="0 0 0"
        rpy="0 0 0" />
      <geometry>
        <mesh
          filename="package://drone/meshes/base_link.STL" />
      </geometry>
      <material
        name="">
        <color
          rgba="1 1 1 1" />
      </material>
    </visual>
    <collision>
      <origin
        xyz="0 0 0"
        rpy="0 0 0" />
      <geometry>
        <mesh
          filename="package://drone/meshes/base_link.STL" />
      </geometry>
    </collision>
  </link>
  <link
    name="link1">
    <inertial>
      <origin
        xyz="1.1432E-08 9.3684E-08 0.0045517"
        rpy="0 0 0" />
      <mass
        value="0.0050793" />
      <inertia
        ixx="7.3747E-06"
        ixy="-2.1019E-07"
        ixz="-9.4002E-13"
        iyy="1.0257E-07"
        iyz="-3.4396E-12"
        izz="7.4268E-06" />
    </inertial>
    <visual>
      <origin
        xyz="0 0 0"
        rpy="0 0 0" />
      <geometry>
        <mesh
          filename="package://drone/meshes/link1.STL" />
      </geometry>
      <material
        name="">
        <color
          rgba="1 1 1 1" />
      </material>
    </visual>
    <collision>
      <origin
        xyz="0 0 0"
        rpy="0 0 0" />
      <geometry>
        <mesh
          filename="package://drone/meshes/link1.STL" />
      </geometry>
    </collision>
  </link>
  <joint
    name="joint1"
    type="continuous">
    <origin
      xyz="-0.065202 -0.2775 -0.13196"
      rpy="-1.5708 -0.66861 3.1416" />
    <parent
      link="base_link" />
    <child
      link="link1" />
    <axis
      xyz="0 0 1" />
  </joint>
  <link
    name="link2">
    <inertial>
      <origin
        xyz="6.6062E-09 -5.727E-08 0.0045478"
        rpy="0 0 0" />
      <mass
        value="0.0050776" />
      <inertia
        ixx="7.3696E-06"
        ixy="2.1017E-07"
        ixz="-7.5917E-13"
        iyy="1.0258E-07"
        iyz="5.9289E-13"
        izz="7.4217E-06" />
    </inertial>
    <visual>
      <origin
        xyz="0 0 0"
        rpy="0 0 0" />
      <geometry>
        <mesh
          filename="package://drone/meshes/link2.STL" />
      </geometry>
      <material
        name="">
        <color
          rgba="1 1 1 1" />
      </material>
    </visual>
    <collision>
      <origin
        xyz="0 0 0"
        rpy="0 0 0" />
      <geometry>
        <mesh
          filename="package://drone/meshes/link2.STL" />
      </geometry>
    </collision>
  </link>
  <joint
    name="joint2"
    type="continuous">
    <origin
      xyz="0.099798 -0.2775 -0.13196"
      rpy="-1.5708 0.36848 -3.1416" />
    <parent
      link="base_link" />
    <child
      link="link2" />
    <axis
      xyz="0 0 1" />
  </joint>
  <link
    name="link3">
    <inertial>
      <origin
        xyz="6.6062E-09 -5.727E-08 0.0045478"
        rpy="0 0 0" />
      <mass
        value="0.0050776" />
      <inertia
        ixx="7.3696E-06"
        ixy="2.1017E-07"
        ixz="-7.5917E-13"
        iyy="1.0258E-07"
        iyz="5.9289E-13"
        izz="7.4217E-06" />
    </inertial>
    <visual>
      <origin
        xyz="0 0 0"
        rpy="0 0 0" />
      <geometry>
        <mesh
          filename="package://drone/meshes/link3.STL" />
      </geometry>
      <material
        name="">
        <color
          rgba="1 1 1 1" />
      </material>
    </visual>
    <collision>
      <origin
        xyz="0 0 0"
        rpy="0 0 0" />
      <geometry>
        <mesh
          filename="package://drone/meshes/link3.STL" />
      </geometry>
    </collision>
  </link>
  <joint
    name="joint3"
    type="continuous">
    <origin
      xyz="-0.065202 -0.2775 0.080545"
      rpy="-1.5708 0.36848 -3.1416" />
    <parent
      link="base_link" />
    <child
      link="link3" />
    <axis
      xyz="0 0 1" />
  </joint>
  <link
    name="link4">
    <inertial>
      <origin
        xyz="1.1432E-08 9.3684E-08 0.0045516"
        rpy="0 0 0" />
      <mass
        value="0.0050793" />
      <inertia
        ixx="7.3746E-06"
        ixy="-2.102E-07"
        ixz="-9.4002E-13"
        iyy="1.0262E-07"
        iyz="-3.4396E-12"
        izz="7.4268E-06" />
    </inertial>
    <visual>
      <origin
        xyz="0 0 0"
        rpy="0 0 0" />
      <geometry>
        <mesh
          filename="package://drone/meshes/link4.STL" />
      </geometry>
      <material
        name="">
        <color
          rgba="1 1 1 1" />
      </material>
    </visual>
    <collision>
      <origin
        xyz="0 0 0"
        rpy="0 0 0" />
      <geometry>
        <mesh
          filename="package://drone/meshes/link4.STL" />
      </geometry>
    </collision>
  </link>
  <joint
    name="joint4"
    type="continuous">
    <origin
      xyz="0.099798 -0.2775 0.080545"
      rpy="1.5708 -1.4927 0" />
    <parent
      link="base_link" />
    <child
      link="link4" />
    <axis
      xyz="0 0 1" />
  </joint>
  <link
    name="link5">
    <inertial>
      <origin
        xyz="0 0 0"
        rpy="0 0 0" />
      <mass
        value="0" />
      <inertia
        ixx="0"
        ixy="0"
        ixz="0"
        iyy="0"
        iyz="0"
        izz="0" />
    </inertial>
    <visual>
      <origin
        xyz="0 0 0"
        rpy="0 0 0" />
      <geometry>
        <mesh
          filename="package://drone/meshes/link5.STL" />
      </geometry>
      <material
        name="">
        <color
          rgba="1 1 1 1" />
      </material>
    </visual>
    <collision>
      <origin
        xyz="0 0 0"
        rpy="0 0 0" />
      <geometry>
        <mesh
          filename="package://drone/meshes/link5.STL" />
      </geometry>
    </collision>
  </link>
  <joint
    name="joint5"
    type="prismatic">
    <origin
      xyz="0.0047981 -0.1925 -0.025997"
      rpy="-1.5708 0.5236 -3.1416" />
    <parent
      link="base_link" />
    <child
      link="link5" />
    <axis
      xyz="0 0 1" />
  </joint>
</robot>
